# Known Bugs in Hazelbean

This document tracks known bugs discovered through comprehensive testing. These bugs cause certain tests to fail intentionally - the test failures are **correct and valuable** as they document bugs that need fixing.

## üîç Important Distinction: CI Infrastructure vs Hazelbean Bugs

### CI Infrastructure Issues (Test Framework - Our Responsibility)
These are problems with the test infrastructure, build process, or CI configuration - NOT bugs in hazelbean functionality:

- ‚úÖ **RESOLVED: Cython Extension Import in CI**
  - **Problem:** Cython extensions not importable in CI environment, causing `ImportError: cannot import name 'cython_functions'`
  - **Root Cause:** Package not installed before running tests - extensions existed but weren't in Python's import path
  - **Solution:** Added `pip install -e .` step in CI workflow to build and install package before tests
  - **Status:** Fixed in `.github/workflows/testing-quality-gates.yml` (lines 88-111, 159-163, 248-251, 302-305)
  - **Impact:** This was blocking ALL tests from running - now resolved
  - **Note:** This is a packaging/build issue, not a hazelbean logic bug

### Known Hazelbean Bugs (Core Software - Upstream Responsibility)
These are actual bugs in hazelbean's core functionality that need fixing by maintainers:

## Bug Status Legend
- üêõ **Open** - Bug exists and needs fixing
- ‚úÖ **Fixed** - Bug has been resolved (tests will pass)
- üîÑ **In Progress** - Bug fix is being worked on

---

## üêõ Error Handling Bug in ProjectFlow add_task() and add_iterator()

**Status:** üêõ Open  
**Discovered:** 2025-09-18  
**Severity:** Medium  
**Component:** `hazelbean/project_flow.py`

### Description
The `add_task()` and `add_iterator()` methods have incorrect error handling logic that causes `AttributeError` instead of the intended `TypeError` when non-callable objects are passed as function parameters.

### Root Cause
The error handling code tries to access the `__name__` attribute of invalid objects before checking if they are callable:

**Lines 593 & 707 in `project_flow.py`:**
```python
if not hasattr(function, '__call__'):
    raise TypeError(
        'Fuction passed to add_task() must be callable. ' + str(function.__name__) + ' was not.')
        #                                                    ^^^^^^^^^^^^^^^^^
        #                                                    This causes AttributeError!
```

### Reproduction
```python
import hazelbean as hb

p = hb.ProjectFlow('/tmp/test')

# These should raise TypeError but raise AttributeError instead
p.add_task("not_a_function")  # AttributeError: 'str' object has no attribute '__name__'
p.add_task(None)              # AttributeError: 'NoneType' object has no attribute '__name__'
p.add_iterator("not_a_function")  # Same issue
p.add_iterator(None)          # Same issue
```

### Expected Behavior
Should raise `TypeError` with message like:
```
TypeError: Function passed to add_task() must be callable. 'not_a_function' was not.
```

### Actual Behavior
Raises `AttributeError` with message like:
```
AttributeError: 'str' object has no attribute '__name__'. Did you mean: '__ne__'?
```

### Affected Code Locations
1. **`hazelbean/project_flow.py:593`** - `add_task()` method
2. **`hazelbean/project_flow.py:707`** - `add_iterator()` method

### Failing Tests (Intentionally)
These tests fail because they expect correct behavior:

**Story 1 & 2 Core Proof Tests:**
- `unit/test_add_task.py::TestAddTaskErrorHandling::test_add_task_invalid_function_error`
- `unit/test_add_task.py::TestAddTaskErrorHandling::test_add_task_none_function_error`
- `unit/test_add_iterator.py::TestAddIteratorErrorHandling::test_add_iterator_invalid_function_error` ‚ö†Ô∏è **xfail**
- `unit/test_add_iterator.py::TestAddIteratorErrorHandling::test_add_iterator_none_function_error` ‚ö†Ô∏è **xfail**

**Story 3 Comprehensive Unit Tests:**
- `unit/test_add_iterator.py::TestErrorHandlingB5::test_non_callable_function_parameter` ‚ö†Ô∏è **xfail**
- `unit/test_add_iterator.py::TestErrorHandlingB5::test_none_function_parameter` ‚ö†Ô∏è **xfail**

**Note:** When this bug is fixed, these tests will automatically start passing.

### Test Status & xfail Markers

**These tests are marked with `@pytest.mark.xfail` to allow CI to pass while documenting the bug:**

- ‚úÖ Tests still run and validate correct behavior
- ‚úÖ CI passes (xfailed tests don't fail builds)
- ‚úÖ Automatic alert when bug is fixed (tests will show XPASSED)
- ‚úÖ Clear tracking of failure rates

**When this bug is fixed in hazelbean:**
1. These tests will show as "XPASSED" (unexpected pass)
2. Remove the `@pytest.mark.xfail` decorators
3. Tests will run as normal passing tests
4. Update this bug status to ‚úÖ Fixed

**xfail marker format:**
```python
@pytest.mark.xfail(
    reason="Known bug: project_flow.py:772 - See KNOWN_BUGS.md",
    strict=True,  # Alert on unexpected pass
    raises=AttributeError  # Current buggy behavior
)
```

### Suggested Fix
Check if the function is callable before trying to access its `__name__` attribute:

```python
if not hasattr(function, '__call__'):
    # Safe way to get function name/description for error message
    func_desc = getattr(function, '__name__', repr(function))
    raise TypeError(
        f'Function passed to add_task() must be callable. {func_desc} was not.')
```

### Additional Notes
- There's also a typo: "Fuction" should be "Function" 
- The same pattern exists in both `add_task()` and `add_iterator()` methods
- This bug affects error message quality but doesn't break core functionality
- Tests correctly expose this issue by expecting the proper `TypeError`

---

## üêõ Inconsistent task_names_defined Tracking Between Methods

**Status:** üêõ Open  
**Discovered:** 2025-09-18  
**Severity:** Medium  
**Component:** `hazelbean/project_flow.py`

### Description
The `add_task()` and `add_iterator()` methods have inconsistent behavior when tracking function names in the `task_names_defined` list. This creates unpredictable behavior when code relies on this list for runtime conditionals.

### Root Cause
Only `add_task()` adds function names to the `task_names_defined` list, while `add_iterator()` does not:

**Line 596 in `add_task()`:**
```python
self.task_names_defined.append(function.__name__)  # ‚úÖ Adds name to list
```

**Lines 700-732 in `add_iterator()`:**
```python
# No corresponding line - missing task_names_defined.append()  # ‚ùå Missing
```

### Reproduction
```python
import hazelbean as hb

p = hb.ProjectFlow('/tmp/test')

def test_task(p): pass
def test_iterator(p): 
    p.iterator_replacements = {'test': ['val'], 'cur_dir_parent_dir': [p.intermediate_dir]}

# add_task() adds to task_names_defined
p.add_task(test_task)
print(len(p.task_names_defined))  # 1 - name added

# add_iterator() does NOT add to task_names_defined  
p.add_iterator(test_iterator)
print(len(p.task_names_defined))  # Still 1 - name not added!
```

### Expected Behavior
Both methods should consistently track function names:
```python
assert 'test_task' in p.task_names_defined      # ‚úÖ Works
assert 'test_iterator' in p.task_names_defined  # ‚ùå Fails - should work
```

### Actual Behavior
Only task names are tracked, iterator names are silently ignored.

### Affected Code Locations
1. **`hazelbean/project_flow.py:596`** - `add_task()` properly tracks names
2. **`hazelbean/project_flow.py:700-732`** - `add_iterator()` missing name tracking

### Failing Tests (Intentionally)
This bug causes these tests to fail - the failures are CORRECT and expose the bug:

**Story 4 Integration Tests:**
- `integration/test_project_flow_task_management.py::TestMixedHierarchyConstruction::test_iterator_with_child_tasks_hierarchy`
- `integration/test_project_flow_task_management.py::TestCrossMethodAttributeManagement::test_task_names_defined_tracking_across_methods`

### Suggested Fix
Add consistent name tracking to `add_iterator()`:

```python
def add_iterator(self, function, project=None, parent=None, run_in_parallel=False, type='iterator', **kwargs):
    # ... existing code ...
    
    # Add this line after iterator creation (around line 713):
    self.task_names_defined.append(function.__name__)
    
    # ... rest of method ...
```

### Additional Notes
- The `task_names_defined` list is used for runtime conditionals (see line 1159 in `execute()`)
- Current inconsistency means iterator-based conditional logic won't work as expected
- Both methods should have identical behavior for name tracking

---

## üêõ Task Attributes Not Inheriting Project-Level Settings

**Status:** üêõ Open  
**Discovered:** 2025-09-18  
**Severity:** Low  
**Component:** `hazelbean/project_flow.py`

### Description
Tasks hardcode certain attributes instead of inheriting them from project-level settings, making it impossible to configure task behavior at the project level.

### Root Cause
The `Task` class constructor hardcodes `report_time_elapsed_when_task_completed = True` instead of inheriting from the project:

**Line 168 in `Task.__init__()`:**
```python
self.report_time_elapsed_when_task_completed = True  # ‚ùå Hardcoded
```

### Reproduction
```python
import hazelbean as hb

p = hb.ProjectFlow('/tmp/test')

# Set project-level setting
p.report_time_elapsed_when_task_completed = False

def test_task(p): pass

# Task should inherit project setting but doesn't
task = p.add_task(test_task)
print(task.report_time_elapsed_when_task_completed)  # True - should be False!
```

### Expected Behavior
Tasks should inherit project-level settings by default:
```python
p.report_time_elapsed_when_task_completed = False
task = p.add_task(test_task)
assert task.report_time_elapsed_when_task_completed == False  # Should inherit
```

### Actual Behavior
Task attributes are hardcoded and ignore project settings.

### Affected Code Locations
1. **`hazelbean/project_flow.py:168`** - `Task.__init__()` hardcodes attribute
2. **Similar pattern may exist for other task attributes**

### Failing Tests (Intentionally)
This bug causes these tests to fail - the failures are CORRECT and expose the bug:

**Story 4 Integration Tests:**
- `integration/test_project_flow_task_management.py::TestConfigurationInheritanceAcrossMethods::test_project_level_settings_respect`

### Suggested Fix
Inherit from project settings with hardcoded value as fallback:

```python
def __init__(self, function, project=None, parent=None, type='task', run=1, skip_existing=0, **kwargs):
    # ... existing code ...
    
    # Replace line 168 with:
    self.report_time_elapsed_when_task_completed = getattr(
        project, 'report_time_elapsed_when_task_completed', True
    )
    
    # ... rest of constructor ...
```

### Additional Notes
- This pattern should be applied to other configurable task attributes
- Logging level inheritance works correctly (good example to follow)
- Iterator tasks may have the same issue
- Default values should still be preserved as fallbacks

---

## üêõ Error Handling Bug in ProjectFlow.add_task() {#add_task_error_handling}

**Status:** üêõ Open  
**Discovered:** 2025-10-03  
**Severity:** Medium  
**Component:** `hazelbean/project_flow.py`

### Description
The `add_task()` method has incorrect error handling logic that causes `AttributeError` instead of the intended `TypeError` when non-callable objects are passed as function parameters. This is the same bug pattern as `add_iterator()` but in a different method.

### Root Cause
The error handling code tries to access the `__name__` attribute of invalid objects before checking if they are callable:

**Lines 655-658 in `project_flow.py`:**
```python
if not hasattr(function, '__call__'):
    raise TypeError(
        'Fuction passed to add_task() must be callable. ' + str(function.__name__) + ' was not.')
        #                                                    ^^^^^^^^^^^^^^^^^
        #                                                    This causes AttributeError!
```

### Reproduction
```python
import hazelbean as hb

p = hb.ProjectFlow('/tmp/test')

# These should raise TypeError but raise AttributeError instead
p.add_task("not_a_function")  # AttributeError: 'str' object has no attribute '__name__'
p.add_task(None)              # AttributeError: 'NoneType' object has no attribute '__name__'
```

### Expected Behavior
Should raise `TypeError` with message like:
```
TypeError: Function passed to add_task() must be callable. 'not_a_function' was not.
```

### Actual Behavior
Raises `AttributeError` with message like:
```
AttributeError: 'str' object has no attribute '__name__'. Did you mean: '__ne__'?
```

### Affected Code Locations
1. **`hazelbean/project_flow.py:655-658`** - `add_task()` method error handler

### Failing Tests (Intentionally)
These tests fail because they expect correct behavior - **the test failures are valuable and correct**:

**Core Proof Tests (Story 1):**
- `unit/test_add_task.py::TestAddTaskErrorHandling::test_add_task_invalid_function_error` ‚ö†Ô∏è **xfail**
- `unit/test_add_task.py::TestAddTaskErrorHandling::test_add_task_none_function_error` ‚ö†Ô∏è **xfail**

### Test Status & xfail Markers

**These tests are marked with `@pytest.mark.xfail` to allow CI to pass while documenting the bug:**

- ‚úÖ Tests still run and validate expected (correct) behavior
- ‚úÖ CI passes (xfailed tests don't fail builds)
- ‚úÖ Automatic alert when bug is fixed (tests will show XPASSED)
- ‚úÖ Bug is tracked and documented

**When this bug is fixed in hazelbean:**
1. These tests will show as "XPASSED" (unexpected pass)
2. Remove the `@pytest.mark.xfail` decorators
3. Tests will run as normal passing tests
4. Update this bug status to ‚úÖ Fixed

**xfail marker format:**
```python
@pytest.mark.xfail(
    reason="Known bug: project_flow.py:655-658 - See KNOWN_BUGS.md #add_task_error_handling",
    strict=True,  # Alert on unexpected pass
    raises=AttributeError  # Current buggy behavior
)
```

### Suggested Fix
Check if the function is callable before trying to access its `__name__` attribute:

```python
if not hasattr(function, '__call__'):
    # Safe way to get function name/description for error message
    func_desc = getattr(function, '__name__', repr(function))
    raise TypeError(
        f'Function passed to add_task() must be callable. {func_desc} was not.')
```

### Additional Notes
- There's also a typo: "Fuction" should be "Function"
- This is the same bug pattern as in `add_iterator()` (see bug above)
- This bug affects error message quality but doesn't break core functionality
- Tests correctly expose this issue by expecting the proper `TypeError`
- Related to existing `add_iterator()` bug - same root cause, different method

---

## üêõ Unusual Exception Type in get_path() for Missing Files {#get_path_exception_type}

**Status:** üêõ Open - Investigation Needed  
**Discovered:** 2025-10-03  
**Severity:** Medium  
**Component:** `hazelbean/project_flow.py` (lines 612, 618)

### Description
The `get_path()` method raises `NameError` when files are not found, which violates Python conventions. The standard Python exception for missing files is `FileNotFoundError` (available since Python 3.3). Using `NameError` is confusing because this exception is typically reserved for undefined variables/names in code, not file system operations.

### Investigation Needed
**It is unclear whether this is:**
1. **Intentional design** - Using `NameError` deliberately to distinguish hazelbean's path resolution from OS-level errors
2. **A bug** - Should be using `FileNotFoundError` to follow Python conventions

**The method has no docstring**, making it impossible to determine intended behavior from documentation.

### Root Cause (If Bug)
The error handling code explicitly raises `NameError`:

**Lines 612, 618 in `project_flow.py`:**
```python
raise NameError('The path given to hb.get_path() does not exist...')
```

**Python convention would be:**
```python
raise FileNotFoundError('The path given to hb.get_path() does not exist...')
```

### Investigation Results (2025-10-03)

**Tested behavior:**
1. ‚úÖ `NameError` is raised for missing files (confirmed)
2. ‚úÖ `leave_ref_path_if_fail=True` works correctly (returns constructed path)
3. ‚úÖ `raise_error_if_fail=False` works correctly (returns constructed path)
4. ‚ùå No docstring exists for the method
5. ‚ùå Error message has grammatical issues ("and or is not available")

**Conclusion:** The parameters work correctly, but the exception type choice is questionable and undocumented.

### Affected Tests
These tests are marked xfail while investigation is pending:

**Edge Case Tests:**
- `unit/test_get_path.py::TestErrorHandlingAndEdgeCases::test_invalid_characters_in_path` ‚ö†Ô∏è **xfail**
- `unit/test_get_path.py::TestErrorHandlingAndEdgeCases::test_path_with_special_characters` ‚ö†Ô∏è **xfail**
- `unit/test_get_path.py::TestErrorHandlingAndEdgeCases::test_missing_file_fallback` ‚ö†Ô∏è **xfail**
- `unit/test_get_path.py::TestErrorHandlingAndEdgeCases::test_very_long_path` ‚ö†Ô∏è **xfail**

**Cloud Storage Tests:**
- `unit/test_get_path.py::TestCloudStorageIntegration::test_google_cloud_bucket_integration` ‚ö†Ô∏è **xfail**
- `unit/test_get_path.py::TestCloudStorageIntegration::test_cloud_path_fallback` ‚ö†Ô∏è **xfail**

### Test Status & xfail Markers

**These tests are marked with `@pytest.mark.xfail` while investigation is pending:**

- ‚úÖ Tests still run (not skipped)
- ‚úÖ CI passes (xfailed tests don't fail builds)
- ‚úÖ Alerts when behavior changes
- ‚úÖ Investigation needed to determine intended behavior

**xfail marker format:**
```python
@pytest.mark.xfail(
    reason="Investigation needed: get_path() raises NameError for missing files (unusual - Python convention is FileNotFoundError). Need to determine if this is intended behavior. See KNOWN_BUGS.md #get_path_exception_type",
    strict=False,
    raises=NameError
)
```

### Possible Fixes (Pending Investigation Results)

**If NameError is a bug (recommended if no strong reason exists):**
```python
# In project_flow.py, lines 612, 618:
if file_not_found:
    if raise_error_if_fail:
        raise FileNotFoundError(f'The path given to hb.get_path() does not exist...')
```

**If NameError is intentional:**
1. Add comprehensive docstring documenting the exception type and why
2. Update tests to expect `NameError`
3. Improve error message grammar ("and or" ‚Üí proper phrasing)

### Additional Notes
- Parameters (`leave_ref_path_if_fail`, `raise_error_if_fail`) work correctly
- Main issues: unusual exception type, no docstring, poor error message
- Impact: Confusion for users expecting standard Python exceptions
- Decision needed from hazelbean maintainers on whether `NameError` is intentional

---

## How to Use This Document

### For Hazelbean Maintainers
1. **Fixing Bugs:** Each section provides exact locations and suggested fixes
2. **Verifying Fixes:** Run the listed failing tests - they should pass after fixes
3. **Status Updates:** Change status from üêõ to ‚úÖ when bugs are resolved

### For Developers
1. **Understanding Test Failures:** Check this file if tests fail unexpectedly
2. **Contributing:** Add new discovered bugs to this file with full documentation
3. **Testing:** Don't modify tests to accommodate bugs - document bugs here instead

### For Test Infrastructure
1. **Test failures listed here are expected and valuable**
2. **Don't adjust tests to hide bugs - let them expose real issues**
3. **When bugs are fixed, corresponding tests will automatically pass**

---

## Bug Report Template

When adding new bugs, use this template:

```markdown
## üêõ [Bug Title]

**Status:** üêõ Open  
**Discovered:** [Date]  
**Severity:** [Low/Medium/High/Critical]  
**Component:** [File path]

### Description
[Clear description of the bug]

### Root Cause
[Technical explanation of what's wrong]

### Reproduction
[Code example showing how to trigger the bug]

### Expected Behavior
[What should happen]

### Actual Behavior
[What actually happens]

### Affected Code Locations
[Specific file and line numbers]

### Failing Tests (Intentionally)
[List of test names that expose this bug]

### Suggested Fix
[Proposed solution]

### Additional Notes
[Any other relevant information]
```

---

## üêõ Missing Name Tracking in add_iterator() {#add_iterator_name_tracking}

**Status:** üêõ Open  
**Discovered:** 2025-10-09  
**Severity:** Medium  
**Component:** `hazelbean/project_flow.py` (line ~778)

### Description
The `add_iterator()` method does not append iterator function names to `task_names_defined` list, unlike `add_task()`, `add_input_task()`, and `add_output_task()` which all track names. This creates inconsistent behavior when code relies on this list for runtime conditionals or task name lookups.

### Root Cause
The `add_iterator()` method is missing a single line that all other task-adding methods have:

**Comparison:**
```python
# add_task() - Line 661
self.task_names_defined.append(function.__name__)  # ‚úÖ Tracks name

# add_input_task() - Line 702  
self.task_names_defined.append(function.__name__)  # ‚úÖ Tracks name

# add_output_task() - Line 740
self.task_names_defined.append(function.__name__)  # ‚úÖ Tracks name

# add_iterator() - Line ~778
# MISSING: self.task_names_defined.append(function.__name__)  # ‚ùå Missing!
```

### Reproduction
```python
import hazelbean as hb

p = hb.ProjectFlow('/tmp/test')

def test_task(p): 
    pass

def test_iterator(p):
    p.iterator_replacements = {
        'test': ['val'], 
        'cur_dir_parent_dir': [p.intermediate_dir]
    }

# add_task tracks name
p.add_task(test_task)
assert 'test_task' in p.task_names_defined  # ‚úÖ Works

# add_iterator does NOT track name
p.add_iterator(test_iterator)
assert 'test_iterator' in p.task_names_defined  # ‚ùå Fails - should work!
```

### Expected Behavior
All task-adding methods should consistently track function names:
```python
p.add_task(test_task)
p.add_iterator(test_iterator)

assert 'test_task' in p.task_names_defined      # ‚úÖ Should work
assert 'test_iterator' in p.task_names_defined  # ‚úÖ Should work (currently fails)
```

### Actual Behavior
Only `add_task()`, `add_input_task()`, and `add_output_task()` track names. Iterator names are silently not added.

### Affected Code Locations
1. **`hazelbean/project_flow.py:~778`** - `add_iterator()` missing the append call

### Failing Tests (Intentionally)
These tests correctly fail and expose the bug:

**Integration Tests (CI Failures):**
- `integration/test_project_flow_task_management.py::TestMixedHierarchyConstruction::test_iterator_with_child_tasks_hierarchy` ‚ö†Ô∏è **xfail**
- `integration/test_project_flow_task_management.py::TestCrossMethodAttributeManagement::test_task_names_defined_tracking_across_methods` ‚ö†Ô∏è **xfail**

### Test Status & xfail Markers

**These tests are marked with `@pytest.mark.xfail` to allow CI to pass while documenting the bug:**

```python
@pytest.mark.xfail(
    reason="Bug in hazelbean/project_flow.py: add_iterator() doesn't append to task_names_defined "
           "(line ~778 missing: self.task_names_defined.append(function.__name__)). "
           "add_task(), add_input_task(), and add_output_task() all do this, but add_iterator() doesn't.",
    strict=False
)
```

- ‚úÖ Tests still run and validate correct behavior
- ‚úÖ CI passes (xfailed tests don't block builds)
- ‚úÖ When bug is fixed, tests will show XPASSED
- ‚úÖ Bug clearly documented and tracked

### Suggested Fix
Add the missing line to `add_iterator()` around line 778:

```python
def add_iterator(self, function, project=None, parent=None, run_in_parallel=False, type='iterator', **kwargs):
    # ... existing code ...
    
    iterator = Task(function, self, parent=parent, type=type, **kwargs)
    iterator.run_in_parallel = run_in_parallel
    
    # ADD THIS LINE:
    self.task_names_defined.append(function.__name__)
    
    setattr(self, iterator.name, iterator)
    # ... rest of method ...
```

### Additional Notes
- The `task_names_defined` list is used throughout the codebase for runtime conditionals
- All iterators are Task objects with `type='iterator'`, so they logically should be tracked
- This is an inconsistency, not an intentional design decision
- Simple one-line fix

---

## üêõ Task report_time_elapsed_when_task_completed Not Inheriting from ProjectFlow {#task_config_inheritance}

**Status:** üêõ Open  
**Discovered:** 2025-10-09  
**Severity:** Medium  
**Component:** `hazelbean/project_flow.py`

### Description
The `Task` class hardcodes `report_time_elapsed_when_task_completed = True` in its constructor instead of inheriting this setting from the ProjectFlow object. This prevents project-level configuration from controlling task timing behavior.

### Root Cause
Multiple issues in the inheritance chain:

1. **ProjectFlow doesn't define the attribute** (line 287-377 in `__init__`)
2. **Task hardcodes it to True** (line 222)
3. **add_task() doesn't set it from project** (line 667 sets logging_level but not this)
4. **add_iterator() doesn't set it from project** (line 781 sets logging_level but not this)

**Comparison with working logging_level inheritance:**
```python
# Task.__init__ - Line 221
self.logging_level = None  # ‚úÖ Initialized to None for inheritance

# add_task() - Line 667
task.logging_level = kwargs.get('logging_level', self.logging_level)  # ‚úÖ Inherits

# Task.__init__ - Line 222
self.report_time_elapsed_when_task_completed = True  # ‚ùå Hardcoded!

# add_task() - No corresponding line
# Missing: task.report_time_elapsed_when_task_completed = ...  # ‚ùå Not set
```

### Reproduction
```python
import hazelbean as hb

p = hb.ProjectFlow('/tmp/test')

# Try to set project-level configuration
p.report_time_elapsed_when_task_completed = False

def test_task(p): 
    pass

# Task should inherit project setting
task = p.add_task(test_task)

print(task.report_time_elapsed_when_task_completed)  
# Actual: True (hardcoded)
# Expected: False (inherited from project)
```

### Expected Behavior
Tasks should inherit project-level settings like `logging_level` does:
```python
p.report_time_elapsed_when_task_completed = False
task = p.add_task(test_task)
assert task.report_time_elapsed_when_task_completed == False  # Should inherit
```

### Actual Behavior
Task always has `report_time_elapsed_when_task_completed = True` regardless of project settings.

### Affected Code Locations
1. **`hazelbean/project_flow.py:287-377`** - ProjectFlow.__init__ should define the attribute
2. **`hazelbean/project_flow.py:222`** - Task.__init__ hardcodes to True
3. **`hazelbean/project_flow.py:667`** - add_task() should set from project
4. **`hazelbean/project_flow.py:781`** - add_iterator() should set from project

### Failing Tests (Intentionally)
This test correctly fails and exposes the bug:

**Integration Test (CI Failure):**
- `integration/test_project_flow_task_management.py::TestConfigurationInheritanceAcrossMethods::test_project_level_settings_respect` ‚ö†Ô∏è **xfail**

### Test Status & xfail Markers

**This test is marked with `@pytest.mark.xfail` to allow CI to pass while documenting the bug:**

```python
@pytest.mark.xfail(
    reason="Bug in hazelbean/project_flow.py: Task.report_time_elapsed_when_task_completed doesn't inherit from ProjectFlow. "
           "Task.__init__ (line 222) hardcodes it to True instead of None. "
           "add_task() and add_iterator() don't set it from project like they do for logging_level. "
           "ProjectFlow.__init__ doesn't even define this attribute. "
           "Should follow the pattern used for logging_level inheritance.",
    strict=False
)
```

### Suggested Fix
Follow the pattern used by `logging_level` inheritance:

**Step 1: Add to ProjectFlow.__init__ (around line 301):**
```python
self.logging_level = logging.INFO
self.report_time_elapsed_when_task_completed = True  # ADD THIS - Default value
```

**Step 2: Change Task.__init__ (line 222):**
```python
# From:
self.report_time_elapsed_when_task_completed = True

# To:
self.report_time_elapsed_when_task_completed = None  # Will be inherited
```

**Step 3: Add to add_task() (after line 667):**
```python
task.logging_level = kwargs.get('logging_level', self.logging_level)
# ADD THIS:
task.report_time_elapsed_when_task_completed = kwargs.get(
    'report_time_elapsed_when_task_completed',
    getattr(self, 'report_time_elapsed_when_task_completed', True)
)
```

**Step 4: Add to add_iterator() (after line 781):**
```python
iterator.logging_level = self.logging_level
# ADD THIS:
iterator.report_time_elapsed_when_task_completed = getattr(
    self, 'report_time_elapsed_when_task_completed', True
)
```

### Additional Notes
- The comment on line 222 says "Will be inherited from project flow" but it's hardcoded
- `logging_level` already follows the correct inheritance pattern
- This affects all tasks and iterators
- Easy fix with clear pattern to follow

---

## üêõ Platform-Specific Buffer Dtype Mismatch in Reclassify Functions {#reclassify_dtype_mismatch}

**Status:** üêõ Open  
**Discovered:** 2025-10-29  
**Severity:** Medium  
**Component:** `hazelbean/spatial_utils.py`, `hazelbean/calculation_core/cython_functions.pyx`

### Description
The reclassify raster functions (`reclassify_raster_hb`, `reclassify_raster_arrayframe`) fail on Linux CI with a buffer dtype mismatch error. Cython functions expect `long` (which maps to `int64` on 64-bit Linux) but receive `int32` arrays, causing `ValueError: Buffer dtype mismatch, expected 'long' but got 'int'`.

### Root Cause
Platform-specific Cython dtype mapping issue:
- **Linux 64-bit:** Cython's `long` type = `int64`
- **macOS:** `long` aligns with expected types (works)
- **The bug:** Code converts rules arrays to `np.int32` in multiple places (lines 3056, 3090, 3589, 3798, 3807 in `spatial_utils.py`) but Cython functions expect `long[::1]` which requires `int64` on Linux

**Cython function signatures:**
```cython
cpdef long[::, ::1] reclassify_int_to_int_by_array(long[::, ::1] input_array, long[::1] rules_array)
cpdef long[::, ::1] reclassify_uint8_to_int_by_array(unsigned char[::, ::1] input_array, long[::1] rules_array)
```

**Problematic code in `spatial_utils.py`:**
```python
# Line 3056, 3090, 3589, 3798, 3807
rules.astype(np.int32)  # ‚ùå Should be np.int64 for Linux compatibility
```

### Reproduction
```python
import hazelbean as hb
import numpy as np

# On Linux CI, this fails:
rules = {235: 34}
output_path = 'test_output.tif'
hb.reclassify_raster_hb('input.tif', rules, output_path)
# ValueError: Buffer dtype mismatch, expected 'long' but got 'int'
```

### Expected Behavior
Reclassify functions should work consistently across platforms (Linux, macOS, Windows).

### Actual Behavior
- ‚úÖ **macOS:** Works (dtype alignment happens to match)
- ‚ùå **Linux CI:** Fails with buffer dtype mismatch
- ‚ùì **Windows:** Unknown (may work or fail depending on platform)

### Affected Code Locations
1. **`hazelbean/spatial_utils.py:3056`** - `rules.astype(np.int32)` for `reclassify_uint8_to_int_by_array`
2. **`hazelbean/spatial_utils.py:3090`** - `rules.astype(np.int32)` for `reclassify_int_to_int_by_array`
3. **`hazelbean/spatial_utils.py:3589`** - `rules.astype(np.int32)` for `reclassify_uint8_to_int_by_array` (arrayframe)
4. **`hazelbean/spatial_utils.py:3798`** - `rules.astype(np.int32)` for `reclassify_uint8_to_int_by_array` (direct call)
5. **`hazelbean/spatial_utils.py:3807`** - `rules.astype(np.int32)` for `reclassify_int_to_int_by_array` (direct call)

### Failing Tests (Intentionally)
These tests are marked xfail while the core bug exists:

- `test_spatial_utils.py::DataStructuresTester::test_reclassify_raster_hb` ‚ö†Ô∏è **xfail**
- `test_spatial_utils.py::DataStructuresTester::test_reclassify_raster_with_negatives_hb` ‚ö†Ô∏è **xfail**
- `test_spatial_utils.py::DataStructuresTester::test_reclassify_raster_arrayframe` ‚ö†Ô∏è **xfail**

### Test Status & xfail Markers

**These tests are marked with `@pytest.mark.xfail` to allow CI to pass while documenting the bug:**

```python
@pytest.mark.xfail(
    reason="Platform-specific dtype bug in hazelbean core: Buffer dtype mismatch on Linux CI. "
           "Cython functions expect 'long' (int64) but receive int32. "
           "Core bug in hazelbean/spatial_utils.py reclassify functions. See KNOWN_BUGS.md",
    strict=False,
    raises=ValueError
)
```

- ‚úÖ Tests still run and document the bug
- ‚úÖ CI passes (xfailed tests don't block builds)
- ‚úÖ When bug is fixed, tests will show XPASSED
- ‚úÖ Platform-specific issue clearly documented

### Suggested Fix
Change `np.int32` to `np.int64` in all locations where rules arrays are passed to Cython functions expecting `long`:

```python
# In spatial_utils.py, lines 3056, 3090, 3589, 3798, 3807:
# Change from:
rules.astype(np.int32)

# To:
rules.astype(np.int64)
```

**Estimated fix size:** Small (5-6 line changes, ~30-45 minutes including testing)

### Additional Notes
- This is a **core hazelbean bug**, not a test infrastructure issue
- Platform-specific behavior makes it harder to catch in local development
- The fix is straightforward but requires careful testing across platforms
- Related to Cython buffer protocol and platform-specific type mappings
- Tests correctly expose this issue by running on Linux CI

---

## üêõ Missing Test Data File in CI {#missing_test_data_csv}

**Status:** üêõ Open  
**Discovered:** 2025-10-29  
**Severity:** Low  
**Component:** Test Infrastructure (`hazelbean_tests/test_spatial_utils.py`)

### Description
The `test_reading_csvs` test fails in CI because it references a CSV file (`cartographic/gadm/gadm_410_adm0_labels.csv`) that is not available in the CI test environment. This is a **test setup issue**, not a core hazelbean bug.

### Root Cause
The test attempts to access a file via `hb.get_path()` that expects to download from cloud storage or access from local test data, but:
- The file is not included in the test data directory
- Cloud storage credentials/config are not set up in CI
- The test data file is missing from the repository

**Test code (line 134):**
```python
test_path = p.get_path('cartographic/gadm/gadm_410_adm0_labels.csv', verbose=True)
# Fails with: NameError: The path given to hb.get_path() does not exist...
```

### Expected Behavior
The test should either:
1. Have the CSV file available in test data, OR
2. Mock/skip the cloud download portion, OR
3. Be skipped if test data is not available

### Actual Behavior
Test fails with `NameError` when trying to access missing file in CI environment.

### Affected Tests
- `test_spatial_utils.py::DataStructuresTester::test_reading_csvs` ‚ö†Ô∏è **skipped**

### Test Status & Skip Marker

**This test is marked with `@pytest.mark.skip` until test data is available:**

```python
@pytest.mark.skip(reason="Missing test data file: cartographic/gadm/gadm_410_adm0_labels.csv - test data not available in CI")
def test_reading_csvs(self):
```

- ‚úÖ Test is skipped (doesn't block CI)
- ‚úÖ Reason clearly documented
- ‚úÖ Can be re-enabled when test data is added

### Suggested Fix
**Option 1: Add test data file** (Preferred)
- Add `cartographic/gadm/gadm_410_adm0_labels.csv` to `hazelbean_tests/data/` directory
- Update test to use local test data path instead of cloud storage

**Option 2: Mock the download**
- Use mock/patch to simulate successful file download
- Test the path resolution logic without requiring actual file

**Option 3: Conditional skip**
- Skip only if file doesn't exist (allows test to run when data is available)

### Additional Notes
- This is a **test infrastructure issue**, not a hazelbean core bug
- The test logic itself is fine - it just needs the test data file
- Low priority - test is skipped so doesn't block CI
- Can be fixed when test data is properly set up

---

## üêõ Cross-Platform Performance Consistency Test Design Issue {#cross_platform_perf_test}

**Status:** üêõ Open (Test Infrastructure Issue)  
**Discovered:** 2025-10-29  
**Severity:** Low  
**Component:** `hazelbean_tests/performance/test_workflows.py::TestPerformanceAggregation::test_cross_platform_performance_consistency`

### Description
The `test_cross_platform_performance_consistency` test fails on CI with low consistency percentages (e.g., `file_io_performance` shows 6.7% consistency when >50% is required). The test is marked as `xfail` because it has a fundamental design flaw.

### Root Cause
**Test Design Flaw:** The test simulates cross-platform testing by running the same performance measurements 3 times on the **same platform** (Linux CI):

```python
platforms = ["linux", "windows", "macos"]  # Simulated platform data
for platform in platforms:
    measurements = {
        "file_io_performance": self._measure_file_io_performance()  # Same measurement repeated
    }
```

**Problems:**
1. **Not actually testing cross-platform consistency** - All 3 "platforms" run on the same Linux CI environment
2. **Measuring repeatability, not cross-platform behavior** - High variance between runs is expected
3. **File I/O variance on CI is legitimate** - Factors include:
   - Filesystem caching differences between runs
   - System load variations
   - I/O scheduler behavior
   - CI environment resource contention
   - Network filesystem latency (if applicable)

**Failure Example:**
```
AssertionError: Metric 'file_io_performance' consistency 6.7% too low
assert 6.736806380451387 > 50
```

### Expected Behavior
The test should either:
1. Actually compare performance across different platforms (requires running on multiple platforms)
2. Compare against stored baseline metrics from different platforms
3. Use more realistic thresholds for CI environment variance
4. Skip when only one platform is available

### Current Status
- ‚úÖ Test marked as `@pytest.mark.xfail` (won't fail CI)
- ‚úÖ Documented in this file
- The test design needs refactoring to properly test cross-platform consistency

### Additional Notes
- This is a **test infrastructure issue**, not a hazelbean core bug
- The test was intended to check cross-platform consistency but doesn't actually do so
- File I/O performance variance on CI is expected behavior, not a bug
- Low priority - test is xfail'd so doesn't block CI
- Can be refactored later if cross-platform testing becomes a priority (Option 4 in proposal)

---

*Last Updated: 2025-10-29 (Added cross-platform performance test design issue)*  
*Next Review: When hazelbean bugs are addressed*
